<?xml version="1.0" encoding="utf-8"?>
<!-- =================================================================================== -->
<!-- |    This document was autogenerated by xacro from src/jueying_ros/jueying_description/urdf/jueying_simple.xacro | -->
<!-- |    EDITING THIS FILE BY HAND IS NOT RECOMMENDED                                 | -->
<!-- =================================================================================== -->
<robot name="jueying">
  <material name="black">
    <color rgba="0.0 0.0 0.0 1.0"/>
  </material>
  <material name="blue">
    <color rgba="0.0 0.0 0.8 1.0"/>
  </material>
  <material name="green">
    <color rgba="0.0 0.8 0.0 1.0"/>
  </material>
  <material name="grey">
    <color rgba="0.2 0.2 0.2 1.0"/>
  </material>
  <material name="silver">
    <color rgba="0.913725490196 0.913725490196 0.847058823529 1.0"/>
  </material>
  <material name="orange">
    <color rgba="1.0 0.423529411765 0.0392156862745 1.0"/>
  </material>
  <material name="brown">
    <color rgba="0.870588235294 0.811764705882 0.764705882353 1.0"/>
  </material>
  <material name="red">
    <color rgba="0.8 0.0 0.0 1.0"/>
  </material>
  <material name="white">
    <color rgba="1.0 1.0 1.0 1.0"/>
  </material>
  <link name="origin_link">
    </link>
  <joint name="origin_baselink_joint" type="fixed">
    <origin rpy="0 0 0" xyz="0 0 0.6"/>
    <parent link="origin_link"/>
    <child link="base_link"/>
  </joint>
  <link name="base_link">
    <inertial>
      <origin rpy="0 0 0" xyz="0.0030652 0.0043949 0.015248"/>
      <mass value="30.0"/>
      <inertia ixx="0.15234" ixy="0.00092094" ixz="-0.0095582" iyy="0.68188" iyz="0.00091552" izz="0.64094"/>
    </inertial>
    <visual>
      <origin rpy="0 0 0" xyz="0 0 0"/>
      <geometry>
        <mesh filename="meshes/base_link.STL"/>
      </geometry>
      <material name="white"/>
    </visual>
    <collision>
      <origin rpy="0 0 0" xyz="0 0 0"/>
      <geometry>
        <box size="0.76 0.18 0.18"/>
      </geometry>
    </collision>
    <collision>
      <origin rpy="0 0 0" xyz="-0.38 0 0"/>
      <geometry>
        <sphere radius="0.09"/>
      </geometry>
    </collision>
    <collision>
      <origin rpy="0 0 0" xyz="0.38 0 0"/>
      <geometry>
        <sphere radius="0.09"/>
      </geometry>
    </collision>
  </link>
  <link name="FL_HipX">
    <inertial>
      <origin rpy="0 0 0" xyz="0.0 0.038 0.0"/>
      <mass value="3.0"/>
      <inertia ixx="0.00084975" ixy="2.5128E-05" ixz="-3.1095E-05" iyy="0.0016235" iyz="1.9684E-05" izz="0.0012084"/>
    </inertial>
    <visual>
      <origin rpy="0 0 0" xyz="0 0 0"/>
      <geometry>
        <mesh filename="meshes/FL_HipX.STL"/>
      </geometry>
      <material name="white"/>
    </visual>
    <collision>
      <origin rpy="0 0 0" xyz="0 0 0"/>
      <geometry>
        <cylinder length="0.204" radius="0.0746"/>
      </geometry>
    </collision>
  </link>
  <joint name="FL_HipX_joint" type="revolute">
    <origin rpy="0 0 0" xyz="0.317 0.136 0"/>
    <parent link="base_link"/>
    <child link="FL_HipX"/>
    <axis xyz="1 0 0"/>
    <limit effort="37.8" lower="-0.39" upper="0.39" velocity="13.6"/>
    <dynamics damping="1.2" friction="0.1"/>
  </joint>
  <link name="FL_HipY">
    <inertial>
      <origin rpy="0 0 0" xyz="0.0 0.026983 -0.047138"/>
      <mass value="6.0"/>
      <inertia ixx="0.0091835" ixy="-5.5596E-05" ixz="-0.00026799" iyy="0.0095232" iyz="-0.0011185" izz="0.0023439"/>
    </inertial>
    <visual>
      <origin rpy="0 0 0" xyz="0 0 0"/>
      <geometry>
        <mesh filename="meshes/FL_HipY.STL"/>
      </geometry>
      <material name="white"/>
    </visual>
    <collision>
      <origin rpy="0 0 0" xyz="0 0 -0.1475"/>
      <geometry>
        <box size="0.038 0.051 0.295"/>
      </geometry>
    </collision>
    <collision>
      <origin rpy="1.5707963268 0 0" xyz="0 0 -0.295"/>
      <geometry>
        <cylinder length="0.051" radius="0.019"/>
      </geometry>
    </collision>
  </link>
  <joint name="FL_HipY_joint" type="revolute">
    <origin rpy="0 0 0" xyz="0.0 0.037 0.0"/>
    <parent link="FL_HipX"/>
    <child link="FL_HipY"/>
    <axis xyz="0 -1 0"/>
    <limit effort="58.3" lower="-2.27" upper="0.18" velocity="13.4"/>
    <dynamics damping="1.2" friction="0.1"/>
  </joint>
  <link name="FL_Knee">
    <inertial>
      <origin rpy="0 0 0" xyz="0.0 0.0 -0.14462"/>
      <mass value="1.0"/>
      <inertia ixx="0.0048214" ixy="-9.1437E-08" ixz="8.5221E-05" iyy="0.0048402" iyz="1.3168E-06" izz="5.8603E-05"/>
    </inertial>
    <visual>
      <origin rpy="0 0 0" xyz="0 0 0"/>
      <geometry>
        <mesh filename="meshes/FL_Knee.STL"/>
      </geometry>
      <material name="white"/>
    </visual>
    <collision>
      <origin rpy="0 0 0" xyz="0 0 -0.15265"/>
      <geometry>
        <box size="0.028 0.028 0.3053"/>
      </geometry>
    </collision>
    <collision>
      <origin rpy="0 0 0" xyz="0 0 -0.3053"/>
      <geometry>
        <sphere radius="0.0305"/>
      </geometry>
    </collision>
  </link>
  <joint name="FL_Knee_joint" type="revolute">
    <origin rpy="0 0 0" xyz="0 0 -0.3"/>
    <parent link="FL_HipY"/>
    <child link="FL_Knee"/>
    <axis xyz="0 -1 0"/>
    <limit effort="58.3" lower="0.66" upper="2.73" velocity="13.4"/>
    <dynamics damping="1.2" friction="0.1"/>
  </joint>
  <link name="FR_HipX">
    <inertial>
      <origin rpy="0 0 0" xyz="0.0 -0.038 0.0"/>
      <mass value="3.0"/>
      <inertia ixx="0.00084975" ixy="2.5128E-05" ixz="-3.1095E-05" iyy="0.0016235" iyz="1.9684E-05" izz="0.0012084"/>
    </inertial>
    <visual>
      <origin rpy="0 0 0" xyz="0 0 0"/>
      <geometry>
        <mesh filename="meshes/FR_HipX.STL"/>
      </geometry>
      <material name="white"/>
    </visual>
    <collision>
      <origin rpy="0 0 0" xyz="0 0 0"/>
      <geometry>
        <cylinder length="0.204" radius="0.0746"/>
      </geometry>
    </collision>
  </link>
  <joint name="FR_HipX_joint" type="revolute">
    <origin rpy="0 0 0" xyz="0.317 -0.136 0"/>
    <parent link="base_link"/>
    <child link="FR_HipX"/>
    <axis xyz="1 0 0"/>
    <limit effort="37.8" lower="-0.39" upper="0.39" velocity="13.6"/>
    <dynamics damping="1.2" friction="0.1"/>
  </joint>
  <link name="FR_HipY">
    <inertial>
      <origin rpy="0 0 0" xyz="0.0 -0.026983 -0.047138"/>
      <mass value="6.0"/>
      <inertia ixx="0.0091835" ixy="-5.5596E-05" ixz="-0.00026799" iyy="0.0095232" iyz="-0.0011185" izz="0.0023439"/>
    </inertial>
    <visual>
      <origin rpy="0 0 0" xyz="0 0 0"/>
      <geometry>
        <mesh filename="meshes/FR_HipY.STL"/>
      </geometry>
      <material name="white"/>
    </visual>
    <collision>
      <origin rpy="0 0 0" xyz="0 0 -0.1475"/>
      <geometry>
        <box size="0.038 0.051 0.295"/>
      </geometry>
    </collision>
    <collision>
      <origin rpy="1.5707963268 0 0" xyz="0 0 -0.295"/>
      <geometry>
        <cylinder length="0.051" radius="0.019"/>
      </geometry>
    </collision>
  </link>
  <joint name="FR_HipY_joint" type="revolute">
    <origin rpy="0 0 0" xyz="0.0 -0.037 0.0"/>
    <parent link="FR_HipX"/>
    <child link="FR_HipY"/>
    <axis xyz="0 -1 0"/>
    <limit effort="58.3" lower="-2.27" upper="0.18" velocity="13.4"/>
    <dynamics damping="1.2" friction="0.1"/>
  </joint>
  <link name="FR_Knee">
    <inertial>
      <origin rpy="0 0 0" xyz="0.0 0.0 -0.14462"/>
      <mass value="1.0"/>
      <inertia ixx="0.0048214" ixy="-9.1437E-08" ixz="8.5221E-05" iyy="0.0048402" iyz="1.3168E-06" izz="5.8603E-05"/>
    </inertial>
    <visual>
      <origin rpy="0 0 0" xyz="0 0 0"/>
      <geometry>
        <mesh filename="meshes/FR_Knee.STL"/>
      </geometry>
      <material name="white"/>
    </visual>
    <collision>
      <origin rpy="0 0 0" xyz="0 0 -0.15265"/>
      <geometry>
        <box size="0.028 0.028 0.3053"/>
      </geometry>
    </collision>
    <collision>
      <origin rpy="0 0 0" xyz="0 0 -0.3053"/>
      <geometry>
        <sphere radius="0.0305"/>
      </geometry>
    </collision>
  </link>
  <joint name="FR_Knee_joint" type="revolute">
    <origin rpy="0 0 0" xyz="0 0 -0.3"/>
    <parent link="FR_HipY"/>
    <child link="FR_Knee"/>
    <axis xyz="0 -1 0"/>
    <limit effort="58.3" lower="0.66" upper="2.73" velocity="13.4"/>
    <dynamics damping="1.2" friction="0.1"/>
  </joint>
  <link name="HL_HipX">
    <inertial>
      <origin rpy="0 0 0" xyz="0.0 0.038 0.0"/>
      <mass value="3.0"/>
      <inertia ixx="0.00084975" ixy="2.5128E-05" ixz="-3.1095E-05" iyy="0.0016235" iyz="1.9684E-05" izz="0.0012084"/>
    </inertial>
    <visual>
      <origin rpy="0 0 0" xyz="0 0 0"/>
      <geometry>
        <mesh filename="meshes/HL_HipX.STL"/>
      </geometry>
      <material name="white"/>
    </visual>
    <collision>
      <origin rpy="0 0 0" xyz="0 0 0"/>
      <geometry>
        <cylinder length="0.204" radius="0.0746"/>
      </geometry>
    </collision>
  </link>
  <joint name="HL_HipX_joint" type="revolute">
    <origin rpy="0 0 0" xyz="-0.317 0.136 0"/>
    <parent link="base_link"/>
    <child link="HL_HipX"/>
    <axis xyz="1 0 0"/>
    <limit effort="37.8" lower="-0.39" upper="0.39" velocity="13.6"/>
    <dynamics damping="1.2" friction="0.1"/>
  </joint>
  <link name="HL_HipY">
    <inertial>
      <origin rpy="0 0 0" xyz="0.0 0.026983 -0.047138"/>
      <mass value="6.0"/>
      <inertia ixx="0.0091835" ixy="-5.5596E-05" ixz="-0.00026799" iyy="0.0095232" iyz="-0.0011185" izz="0.0023439"/>
    </inertial>
    <visual>
      <origin rpy="0 0 0" xyz="0 0 0"/>
      <geometry>
        <mesh filename="meshes/HL_HipY.STL"/>
      </geometry>
      <material name="white"/>
    </visual>
    <collision>
      <origin rpy="0 0 0" xyz="0 0 -0.1475"/>
      <geometry>
        <box size="0.038 0.051 0.295"/>
      </geometry>
    </collision>
    <collision>
      <origin rpy="1.5707963268 0 0" xyz="0 0 -0.295"/>
      <geometry>
        <cylinder length="0.051" radius="0.019"/>
      </geometry>
    </collision>
  </link>
  <joint name="HL_HipY_joint" type="revolute">
    <origin rpy="0 0 0" xyz="0.0 0.037 0.0"/>
    <parent link="HL_HipX"/>
    <child link="HL_HipY"/>
    <axis xyz="0 -1 0"/>
    <limit effort="58.3" lower="-2.27" upper="0.18" velocity="13.4"/>
    <dynamics damping="1.2" friction="0.1"/>
  </joint>
  <link name="HL_Knee">
    <inertial>
      <origin rpy="0 0 0" xyz="0.0 0.0 -0.14462"/>
      <mass value="1.0"/>
      <inertia ixx="0.0048214" ixy="-9.1437E-08" ixz="8.5221E-05" iyy="0.0048402" iyz="1.3168E-06" izz="5.8603E-05"/>
    </inertial>
    <visual>
      <origin rpy="0 0 0" xyz="0 0 0"/>
      <geometry>
        <mesh filename="meshes/HL_Knee.STL"/>
      </geometry>
      <material name="white"/>
    </visual>
    <collision>
      <origin rpy="0 0 0" xyz="0 0 -0.15265"/>
      <geometry>
        <box size="0.028 0.028 0.3053"/>
      </geometry>
    </collision>
    <collision>
      <origin rpy="0 0 0" xyz="0 0 -0.3053"/>
      <geometry>
        <sphere radius="0.0305"/>
      </geometry>
    </collision>
  </link>
  <joint name="HL_Knee_joint" type="revolute">
    <origin rpy="0 0 0" xyz="0 0 -0.3"/>
    <parent link="HL_HipY"/>
    <child link="HL_Knee"/>
    <axis xyz="0 -1 0"/>
    <limit effort="58.3" lower="0.66" upper="2.73" velocity="13.4"/>
    <dynamics damping="1.2" friction="0.1"/>
  </joint>
  <link name="HR_HipX">
    <inertial>
      <origin rpy="0 0 0" xyz="0.0 -0.038 0.0"/>
      <mass value="3.0"/>
      <inertia ixx="0.00084975" ixy="2.5128E-05" ixz="-3.1095E-05" iyy="0.0016235" iyz="1.9684E-05" izz="0.0012084"/>
    </inertial>
    <visual>
      <origin rpy="0 0 0" xyz="0 0 0"/>
      <geometry>
        <mesh filename="meshes/HR_HipX.STL"/>
      </geometry>
      <material name="white"/>
    </visual>
    <collision>
      <origin rpy="0 0 0" xyz="0 0 0"/>
      <geometry>
        <cylinder length="0.204" radius="0.0746"/>
      </geometry>
    </collision>
  </link>
  <joint name="HR_HipX_joint" type="revolute">
    <origin rpy="0 0 0" xyz="-0.317 -0.136 0"/>
    <parent link="base_link"/>
    <child link="HR_HipX"/>
    <axis xyz="1 0 0"/>
    <limit effort="37.8" lower="-0.39" upper="0.39" velocity="13.6"/>
    <dynamics damping="1.2" friction="0.1"/>
  </joint>
  <link name="HR_HipY">
    <inertial>
      <origin rpy="0 0 0" xyz="0.0 -0.026983 -0.047138"/>
      <mass value="6.0"/>
      <inertia ixx="0.0091835" ixy="-5.5596E-05" ixz="-0.00026799" iyy="0.0095232" iyz="-0.0011185" izz="0.0023439"/>
    </inertial>
    <visual>
      <origin rpy="0 0 0" xyz="0 0 0"/>
      <geometry>
        <mesh filename="meshes/HR_HipY.STL"/>
      </geometry>
      <material name="white"/>
    </visual>
    <collision>
      <origin rpy="0 0 0" xyz="0 0 -0.1475"/>
      <geometry>
        <box size="0.038 0.051 0.295"/>
      </geometry>
    </collision>
    <collision>
      <origin rpy="1.5707963268 0 0" xyz="0 0 -0.295"/>
      <geometry>
        <cylinder length="0.051" radius="0.019"/>
      </geometry>
    </collision>
  </link>
  <joint name="HR_HipY_joint" type="revolute">
    <origin rpy="0 0 0" xyz="0.0 -0.037 0.0"/>
    <parent link="HR_HipX"/>
    <child link="HR_HipY"/>
    <axis xyz="0 -1 0"/>
    <limit effort="58.3" lower="-2.27" upper="0.18" velocity="13.4"/>
    <dynamics damping="1.2" friction="0.1"/>
  </joint>
  <link name="HR_Knee">
    <inertial>
      <origin rpy="0 0 0" xyz="0.0 0.0 -0.14462"/>
      <mass value="1.0"/>
      <inertia ixx="0.0048214" ixy="-9.1437E-08" ixz="8.5221E-05" iyy="0.0048402" iyz="1.3168E-06" izz="5.8603E-05"/>
    </inertial>
    <visual>
      <origin rpy="0 0 0" xyz="0 0 0"/>
      <geometry>
        <mesh filename="meshes/HR_Knee.STL"/>
      </geometry>
      <material name="white"/>
    </visual>
    <collision>
      <origin rpy="0 0 0" xyz="0 0 -0.15265"/>
      <geometry>
        <box size="0.028 0.028 0.3053"/>
      </geometry>
    </collision>
    <collision>
      <origin rpy="0 0 0" xyz="0 0 -0.3053"/>
      <geometry>
        <sphere radius="0.0305"/>
      </geometry>
    </collision>
  </link>
  <joint name="HR_Knee_joint" type="revolute">
    <origin rpy="0 0 0" xyz="0 0 -0.3"/>
    <parent link="HR_HipY"/>
    <child link="HR_Knee"/>
    <axis xyz="0 -1 0"/>
    <limit effort="58.3" lower="0.66" upper="2.73" velocity="13.4"/>
    <dynamics damping="1.2" friction="0.1"/>
  </joint>
</robot>

